<?xml version="1.0"?>
  <sdf version='1.7'>
    <world name='default'>
      <light name='sun' type='directional'>
        <cast_shadows>1</cast_shadows>
        <pose>0 0 10 0 -0 0</pose>
        <diffuse>0.8 0.8 0.8 1</diffuse>
        <specular>0.2 0.2 0.2 1</specular>
        <attenuation>
          <range>1000</range>
          <constant>0.9</constant>
          <linear>0.01</linear>
          <quadratic>0.001</quadratic>
        </attenuation>
        <direction>-0.5 0.1 -0.9</direction>
        <spot>
          <inner_angle>0</inner_angle>
          <outer_angle>0</outer_angle>
          <falloff>0</falloff>
        </spot>
      </light>
      <model name='ground_plane'>
        <static>1</static>
        <link name='link'>
          <collision name='collision'>
            <geometry>
              <plane>
                <normal>0 0 1</normal>
                <size>100 100</size>
              </plane>
            </geometry>
            <surface>
              <friction>
                <ode>
                  <mu>100</mu>
                  <mu2>50</mu2>
                </ode>
                <torsional>
                  <ode/>
                </torsional>
              </friction>
              <contact>
                <ode/>
              </contact>
              <bounce/>
            </surface>
            <max_contacts>10</max_contacts>
          </collision>
          <visual name='visual'>
            <cast_shadows>0</cast_shadows>
            <geometry>
              <plane>
                <normal>0 0 1</normal>
                <size>100 100</size>
              </plane>
            </geometry>
            <material>
              <script>
                <uri>file://media/materials/scripts/gazebo.material</uri>
                <name>Gazebo/Grey</name>
              </script>
            </material>
          </visual>
          <self_collide>0</self_collide>
          <enable_wind>0</enable_wind>
          <kinematic>0</kinematic>
        </link>
      </model>
      <gravity>0 0 -9.8</gravity>
      <magnetic_field>6e-06 2.3e-05 -4.2e-05</magnetic_field>
      <atmosphere type='adiabatic'/>
      <physics type='ode'>
        <max_step_size>0.001</max_step_size>
        <real_time_factor>1</real_time_factor>
        <real_time_update_rate>1000</real_time_update_rate>
      </physics>
      <scene>
        <ambient>0.4 0.4 0.4 1</ambient>
        <background>0.7 0.7 0.7 1</background>
        <shadows>1</shadows>
      </scene>
      <audio>
        <device>default</device>
      </audio>
      <wind/>
      <spherical_coordinates>
        <surface_model>EARTH_WGS84</surface_model>
        <latitude_deg>0</latitude_deg>
        <longitude_deg>0</longitude_deg>
        <elevation>0</elevation>
        <heading_deg>0</heading_deg>
      </spherical_coordinates>
      <model name='environment'>
        <joint name='fixed_shelf' type='fixed'>
          <pose relative_to='__model__'>0 0 0 0 -0 0</pose>
          <parent>world</parent>
          <child>shelf</child>
        </joint>
        <link name='shelf'>
          <pose relative_to='fixed_shelf'>0 0 0 0 -0 0</pose>
          <inertial>
            <pose>0 0.3 0 0 -0 0</pose>
            <mass>316</mass>
            <inertia>
              <ixx>68.8</ixx>
              <ixy>7.56</ixy>
              <ixz>-0.58</ixz>
              <iyy>148.1</iyy>
              <iyz>-6.9</iyz>
              <izz>182.29</izz>
            </inertia>
          </inertial>
          <collision name='shelf_collision'>
            <pose>0 0.3 0 0 -0 0</pose>
            <geometry>
              <mesh>
                <scale>1 1 1</scale>
                <uri>model://robot_description/meshes/shelf.STL</uri>
              </mesh>
            </geometry>
            <surface>
              <contact>
                <ode/>
              </contact>
              <friction>
                <ode/>
                <torsional>
                  <ode/>
                </torsional>
              </friction>
              <bounce/>
            </surface>
            <max_contacts>10</max_contacts>
          </collision>
          <visual name='shelf_visual'>
            <pose>0 0.3 0 0 -0 0</pose>
            <geometry>
              <mesh>
                <scale>1 1 1</scale>
                <uri>model://robot_description/meshes/shelf.STL</uri>
              </mesh>
            </geometry>
            <material>
              <script>
                <name>Gazebo/White</name>
                <uri>file://media/materials/scripts/gazebo.material</uri>
              </script>
            </material>
          </visual>
          <self_collide>0</self_collide>
          <enable_wind>0</enable_wind>
          <kinematic>0</kinematic>
        </link>
        <pose>0 0 0 0 -0 0</pose>
      </model>
      <model name='cylinder_object'>
        <joint name='objL_prisX' type='prismatic'>
          <pose relative_to='__model__'>0.85 0.20 0.45 0 -0 0</pose>
          <parent>world</parent>
          <child>objL_slideX</child>
          <axis>
            <xyz>1 0 0</xyz>
            <limit>
              <lower>-0.8</lower>
              <upper>0.8</upper>
              <effort>0</effort>
              <velocity>0</velocity>
            </limit>
            <dynamics>
              <damping>0</damping>
              <friction>0</friction>
              <spring_reference>0</spring_reference>
              <spring_stiffness>0</spring_stiffness>
            </dynamics>
          </axis>
        </joint>
        <link name='objL_slideX'>
          <pose relative_to='objL_prisX'>0 0 0 0 -0 0</pose>
          <inertial>
            <pose>0 0 0 0 -0 0</pose>
            <mass>0.01</mass>
            <inertia>
              <ixx>0.01</ixx>
              <ixy>0</ixy>
              <ixz>0</ixz>
              <iyy>0.01</iyy>
              <iyz>0</iyz>
              <izz>0.01</izz>
            </inertia>
          </inertial>
          <self_collide>0</self_collide>
          <enable_wind>0</enable_wind>
          <kinematic>0</kinematic>
        </link>
        <joint name='objL_prisY' type='prismatic'>
          <pose relative_to='objL_slideX'>0 0 0 0 -0 0</pose>
          <parent>objL_slideX</parent>
          <child>objL_slideY</child>
          <axis>
            <xyz>0 1 0</xyz>
            <limit>
              <lower>-0.8</lower>
              <upper>0.8</upper>
              <effort>0</effort>
              <velocity>0</velocity>
            </limit>
            <dynamics>
              <damping>0</damping>
              <friction>0</friction>
              <spring_reference>0</spring_reference>
              <spring_stiffness>0</spring_stiffness>
            </dynamics>
          </axis>
        </joint>
        <link name='objL_slideY'>
          <pose relative_to='objL_prisY'>0 0 0 0 -0 0</pose>
          <inertial>
            <pose>0 0 0 0 -0 0</pose>
            <mass>0.01</mass>
            <inertia>
              <ixx>0.01</ixx>
              <ixy>0</ixy>
              <ixz>0</ixz>
              <iyy>0.01</iyy>
              <iyz>0</iyz>
              <izz>0.01</izz>
            </inertia>
          </inertial>
          <self_collide>0</self_collide>
          <enable_wind>0</enable_wind>
          <kinematic>0</kinematic>
        </link>
        <joint name='objL_prisZ' type='prismatic'>
          <pose relative_to='objL_slideY'>0 0 0 0 -0 0</pose>
          <parent>objL_slideY</parent>
          <child>objL_slideZ</child>
          <axis>
            <xyz>0 0 1</xyz>
            <limit>
              <lower>-0.8</lower>
              <upper>0.8</upper>
              <effort>0</effort>
              <velocity>0</velocity>
            </limit>
            <dynamics>
              <damping>0</damping>
              <friction>0</friction>
              <spring_reference>0</spring_reference>
              <spring_stiffness>0</spring_stiffness>
            </dynamics>
          </axis>
        </joint>
        <link name='objL_slideZ'>
          <pose relative_to='objL_prisZ'>0 0 0 0 -0 0</pose>
          <inertial>
            <pose>0 0 0 0 -0 0</pose>
            <mass>0.01</mass>
            <inertia>
              <ixx>0.01</ixx>
              <ixy>0</ixy>
              <ixz>0</ixz>
              <iyy>0.01</iyy>
              <iyz>0</iyz>
              <izz>0.01</izz>
            </inertia>
          </inertial>
          <self_collide>0</self_collide>
          <enable_wind>0</enable_wind>
          <kinematic>0</kinematic>
        </link>
        <joint name='objL_revolX' type='revolute'>
          <pose relative_to='objL_slideZ'>0 0 0 0 -0 0</pose>
          <parent>objL_slideZ</parent>
          <child>objL_rotateX</child>
          <axis>
            <xyz>1 0 0</xyz>
            <limit>
              <lower>-62.8319</lower>
              <upper>62.8319</upper>
              <effort>0</effort>
              <velocity>0</velocity>
            </limit>
            <dynamics>
              <damping>0</damping>
              <friction>0</friction>
              <spring_reference>0</spring_reference>
              <spring_stiffness>0</spring_stiffness>
            </dynamics>
          </axis>
        </joint>
        <link name='objL_rotateX'>
          <pose relative_to='objL_revolX'>0 0 0 0 -0 0</pose>
          <inertial>
            <pose>0 0 0 0 -0 0</pose>
            <mass>0.01</mass>
            <inertia>
              <ixx>0.01</ixx>
              <ixy>0</ixy>
              <ixz>0</ixz>
              <iyy>0.01</iyy>
              <iyz>0</iyz>
              <izz>0.01</izz>
            </inertia>
          </inertial>
          <self_collide>0</self_collide>
          <enable_wind>0</enable_wind>
          <kinematic>0</kinematic>
        </link>
        <joint name='objL_revolY' type='revolute'>
          <pose relative_to='objL_rotateX'>0 0 0 0 -0 0</pose>
          <parent>objL_rotateX</parent>
          <child>objL_rotateY</child>
          <axis>
            <xyz>0 1 0</xyz>
            <limit>
              <lower>-62.8319</lower>
              <upper>62.8319</upper>
              <effort>0</effort>
              <velocity>0</velocity>
            </limit>
            <dynamics>
              <damping>0</damping>
              <friction>0</friction>
              <spring_reference>0</spring_reference>
              <spring_stiffness>0</spring_stiffness>
            </dynamics>
          </axis>
        </joint>
        <link name='objL_rotateY'>
          <pose relative_to='objL_revolY'>0 0 0 0 -0 0</pose>
          <inertial>
            <pose>0 0 0 0 -0 0</pose>
            <mass>0.01</mass>
            <inertia>
              <ixx>0.01</ixx>
              <ixy>0</ixy>
              <ixz>0</ixz>
              <iyy>0.01</iyy>
              <iyz>0</iyz>
              <izz>0.01</izz>
            </inertia>
          </inertial>
          <self_collide>0</self_collide>
          <enable_wind>0</enable_wind>
          <kinematic>0</kinematic>
        </link>
        <joint name='objL_revolZ' type='revolute'>
          <pose relative_to='objL_rotateY'>0 0 0 0 -0 0</pose>
          <parent>objL_rotateY</parent>
          <child>objL</child>
          <axis>
            <xyz>0 0 1</xyz>
            <limit>
              <lower>-62.8319</lower>
              <upper>62.8319</upper>
              <effort>0</effort>
              <velocity>0</velocity>
            </limit>
            <dynamics>
              <damping>0</damping>
              <friction>0</friction>
              <spring_reference>0</spring_reference>
              <spring_stiffness>0</spring_stiffness>
            </dynamics>
          </axis>
        </joint>
        <link name='objL'>
          <pose relative_to='objL_revolZ'>0 0 0 0 -0 0</pose>
          <inertial>
            <pose>0 0 0 0 -0 0</pose>
            <mass>0.01</mass>
            <inertia>
              <ixx>1.23333e-05</ixx>
              <ixy>0</ixy>
              <ixz>0</ixz>
              <iyy>1.23333e-05</iyy>
              <iyz>0</iyz>
              <izz>8e-06</izz>
            </inertia>
          </inertial>
          <collision name='objL_collision'>
            <pose>0 0 0 0 -0 0</pose>
            <geometry>
              <cylinder>
                <length>0.1</length>
                <radius>0.04</radius>
              </cylinder>
            </geometry>
            <surface>
              <contact>
                <ode/>
              </contact>
              <friction>
                <ode/>
                <torsional>
                  <ode/>
                </torsional>
              </friction>
              <bounce/>
            </surface>
            <max_contacts>10</max_contacts>
          </collision>
          <visual name='objL_visual'>
            <pose>0 0 0 0 -0 0</pose>
            <geometry>
              <cylinder>
                <length>0.1</length>
                <radius>0.04</radius>
              </cylinder>
            </geometry>
            <material>
              <script>
                <name>Gazebo/Black</name>
                <uri>file://media/materials/scripts/gazebo.material</uri>
              </script>
            </material>
          </visual>
          <self_collide>0</self_collide>
          <enable_wind>0</enable_wind>
          <kinematic>0</kinematic>
        </link>
        <joint name='objR_prisX' type='prismatic'>
          <pose relative_to='__model__'>-0.85 0.20 0.45 0 -0 0</pose>
          <parent>world</parent>
          <child>objR_slideX</child>
          <axis>
            <xyz>1 0 0</xyz>
            <limit>
              <lower>-0.8</lower>
              <upper>0.8</upper>
              <effort>0</effort>
              <velocity>0</velocity>
            </limit>
            <dynamics>
              <damping>0</damping>
              <friction>0</friction>
              <spring_reference>0</spring_reference>
              <spring_stiffness>0</spring_stiffness>
            </dynamics>
          </axis>
        </joint>
        <link name='objR_slideX'>
          <pose relative_to='objR_prisX'>0 0 0 0 -0 0</pose>
          <inertial>
            <pose>0 0 0 0 -0 0</pose>
            <mass>0.01</mass>
            <inertia>
              <ixx>0.01</ixx>
              <ixy>0</ixy>
              <ixz>0</ixz>
              <iyy>0.01</iyy>
              <iyz>0</iyz>
              <izz>0.01</izz>
            </inertia>
          </inertial>
          <self_collide>0</self_collide>
          <enable_wind>0</enable_wind>
          <kinematic>0</kinematic>
        </link>
        <joint name='objR_prisY' type='prismatic'>
          <pose relative_to='objR_slideX'>0 0 0 0 -0 0</pose>
          <parent>objR_slideX</parent>
          <child>objR_slideY</child>
          <axis>
            <xyz>0 1 0</xyz>
            <limit>
              <lower>-0.8</lower>
              <upper>0.8</upper>
              <effort>0</effort>
              <velocity>0</velocity>
            </limit>
            <dynamics>
              <damping>0</damping>
              <friction>0</friction>
              <spring_reference>0</spring_reference>
              <spring_stiffness>0</spring_stiffness>
            </dynamics>
          </axis>
        </joint>
        <link name='objR_slideY'>
          <pose relative_to='objR_prisY'>0 0 0 0 -0 0</pose>
          <inertial>
            <pose>0 0 0 0 -0 0</pose>
            <mass>0.01</mass>
            <inertia>
              <ixx>0.01</ixx>
              <ixy>0</ixy>
              <ixz>0</ixz>
              <iyy>0.01</iyy>
              <iyz>0</iyz>
              <izz>0.01</izz>
            </inertia>
          </inertial>
          <self_collide>0</self_collide>
          <enable_wind>0</enable_wind>
          <kinematic>0</kinematic>
        </link>
        <joint name='objR_prisZ' type='prismatic'>
          <pose relative_to='objR_slideY'>0 0 0 0 -0 0</pose>
          <parent>objR_slideY</parent>
          <child>objR_slideZ</child>
          <axis>
            <xyz>0 0 1</xyz>
            <limit>
              <lower>-0.8</lower>
              <upper>0.8</upper>
              <effort>0</effort>
              <velocity>0</velocity>
            </limit>
            <dynamics>
              <damping>0</damping>
              <friction>0</friction>
              <spring_reference>0</spring_reference>
              <spring_stiffness>0</spring_stiffness>
            </dynamics>
          </axis>
        </joint>
        <link name='objR_slideZ'>
          <pose relative_to='objR_prisZ'>0 0 0 0 -0 0</pose>
          <inertial>
            <pose>0 0 0 0 -0 0</pose>
            <mass>0.01</mass>
            <inertia>
              <ixx>0.01</ixx>
              <ixy>0</ixy>
              <ixz>0</ixz>
              <iyy>0.01</iyy>
              <iyz>0</iyz>
              <izz>0.01</izz>
            </inertia>
          </inertial>
          <self_collide>0</self_collide>
          <enable_wind>0</enable_wind>
          <kinematic>0</kinematic>
        </link>
        <joint name='objR_revolX' type='revolute'>
          <pose relative_to='objR_slideZ'>0 0 0 0 -0 0</pose>
          <parent>objR_slideZ</parent>
          <child>objR_rotateX</child>
          <axis>
            <xyz>1 0 0</xyz>
            <limit>
              <lower>-62.8319</lower>
              <upper>62.8319</upper>
              <effort>0</effort>
              <velocity>0</velocity>
            </limit>
            <dynamics>
              <damping>0</damping>
              <friction>0</friction>
              <spring_reference>0</spring_reference>
              <spring_stiffness>0</spring_stiffness>
            </dynamics>
          </axis>
        </joint>
        <link name='objR_rotateX'>
          <pose relative_to='objR_revolX'>0 0 0 0 -0 0</pose>
          <inertial>
            <pose>0 0 0 0 -0 0</pose>
            <mass>0.01</mass>
            <inertia>
              <ixx>0.01</ixx>
              <ixy>0</ixy>
              <ixz>0</ixz>
              <iyy>0.01</iyy>
              <iyz>0</iyz>
              <izz>0.01</izz>
            </inertia>
          </inertial>
          <self_collide>0</self_collide>
          <enable_wind>0</enable_wind>
          <kinematic>0</kinematic>
        </link>
        <joint name='objR_revolY' type='revolute'>
          <pose relative_to='objR_rotateX'>0 0 0 0 -0 0</pose>
          <parent>objR_rotateX</parent>
          <child>objR_rotateY</child>
          <axis>
            <xyz>0 1 0</xyz>
            <limit>
              <lower>-62.8319</lower>
              <upper>62.8319</upper>
              <effort>0</effort>
              <velocity>0</velocity>
            </limit>
            <dynamics>
              <damping>0</damping>
              <friction>0</friction>
              <spring_reference>0</spring_reference>
              <spring_stiffness>0</spring_stiffness>
            </dynamics>
          </axis>
        </joint>
        <link name='objR_rotateY'>
          <pose relative_to='objR_revolY'>0 0 0 0 -0 0</pose>
          <inertial>
            <pose>0 0 0 0 -0 0</pose>
            <mass>0.01</mass>
            <inertia>
              <ixx>0.01</ixx>
              <ixy>0</ixy>
              <ixz>0</ixz>
              <iyy>0.01</iyy>
              <iyz>0</iyz>
              <izz>0.01</izz>
            </inertia>
          </inertial>
          <self_collide>0</self_collide>
          <enable_wind>0</enable_wind>
          <kinematic>0</kinematic>
        </link>
        <joint name='objR_revolZ' type='revolute'>
          <pose relative_to='objR_rotateY'>0 0 0 0 -0 0</pose>
          <parent>objR_rotateY</parent>
          <child>objR</child>
          <axis>
            <xyz>0 0 1</xyz>
            <limit>
              <lower>-62.8319</lower>
              <upper>62.8319</upper>
              <effort>0</effort>
              <velocity>0</velocity>
            </limit>
            <dynamics>
              <damping>0</damping>
              <friction>0</friction>
              <spring_reference>0</spring_reference>
              <spring_stiffness>0</spring_stiffness>
            </dynamics>
          </axis>
        </joint>
        <link name='objR'>
          <pose relative_to='objR_revolZ'>0 0 0 0 -0 0</pose>
          <inertial>
            <pose>0 0 0 0 -0 0</pose>
            <mass>0.01</mass>
            <inertia>
              <ixx>1.23333e-05</ixx>
              <ixy>0</ixy>
              <ixz>0</ixz>
              <iyy>1.23333e-05</iyy>
              <iyz>0</iyz>
              <izz>8e-06</izz>
            </inertia>
          </inertial>
          <collision name='objR_collision'>
            <pose>0 0 0 0 -0 0</pose>
            <geometry>
              <cylinder>
                <length>0.1</length>
                <radius>0.04</radius>
              </cylinder>
            </geometry>
            <surface>
              <contact>
                <ode/>
              </contact>
              <friction>
                <ode/>
                <torsional>
                  <ode/>
                </torsional>
              </friction>
              <bounce/>
            </surface>
            <max_contacts>10</max_contacts>
          </collision>
          <visual name='objR_visual'>
            <pose>0 0 0 0 -0 0</pose>
            <geometry>
              <cylinder>
                <length>0.1</length>
                <radius>0.04</radius>
              </cylinder>
            </geometry>
            <material>
              <script>
                <name>Gazebo/Black</name>
                <uri>file://media/materials/scripts/gazebo.material</uri>
              </script>
            </material>
          </visual>
          <self_collide>0</self_collide>
          <enable_wind>0</enable_wind>
          <kinematic>0</kinematic>
        </link>
        <static>0</static>
        <plugin name='gazebo_ros_joint_state_publisher_cylinder' filename='libgazebo_ros_joint_state_publisher.so'>
          <joint_name>objR_prisX</joint_name>
          <joint_name>objR_prisY</joint_name>
          <joint_name>objR_prisZ</joint_name>
          <joint_name>objR_revolX</joint_name>
          <joint_name>objR_revolY</joint_name>
          <joint_name>objR_revolZ</joint_name>
          <joint_name>objL_prisX</joint_name>
          <joint_name>objL_prisY</joint_name>
          <joint_name>objL_prisZ</joint_name>
          <joint_name>objL_revolX</joint_name>
          <joint_name>objL_revolY</joint_name>
          <joint_name>objL_revolZ</joint_name>
        </plugin>
        <pose>0 0 0 0 -0 0</pose>
      </model>
      <state world_name='default'>
        <sim_time>61 778000000</sim_time>
        <real_time>63 235067625</real_time>
        <wall_time>1690260318 353366821</wall_time>
        <iterations>61778</iterations>
        <model name='cylinder_object'>
          <pose>0.010106 -0 0 0 -0 0</pose>
          <scale>1 1 1</scale>
          <link name='objL'>
            <pose>0.860105 0.205045 0.450003 -3e-05 -5.8e-05 0.03325</pose>
            <velocity>-0.000198 -5.3e-05 0.00052 -0.001069 -0.004201 -0.002581</velocity>
            <acceleration>-0.592882 -0.05818 -8.45101 -0.953868 0.384157 -2.58083</acceleration>
            <wrench>-0.005929 -0.000582 -0.08451 0 -0 0</wrench>
          </link>
          <link name='objL_rotateX'>
            <pose>0.860106 0.205045 0.450003 -1.6e-05 -0 -0</pose>
            <velocity>-4.6e-05 1.9e-05 0.000538 -0.000741 0 0</velocity>
            <acceleration>-0.369266 0.007136 -8.45037 -0.003986 -0 3.5e-05</acceleration>
            <wrench>-0.003693 7.1e-05 -0.084504 0 -0 0</wrench>
          </link>
          <link name='objL_rotateY'>
            <pose>0.860106 0.205045 0.450003 -1.6e-05 -8.6e-05 0</pose>
            <velocity>-5.7e-05 1.6e-05 0.000538 -0.000742 -0.002758 0</velocity>
            <acceleration>-0.38615 0.004952 -8.45035 -0.004281 0.37027 2.9e-05</acceleration>
            <wrench>-0.003861 5e-05 -0.084504 0 -0 0</wrench>
          </link>
          <link name='objL_slideX'>
            <pose>0.860106 0.20 0.45 0 -0 0</pose>
            <velocity>-4.4e-05 -0 0 -0 -0 -0</velocity>
            <acceleration>-0.365909 0 -0 -0 -0 -1.6e-05</acceleration>
            <wrench>-0.003659 0 -0 0 -0 0</wrench>
          </link>
          <link name='objL_slideY'>
            <pose>0.860106 0.205045 0.45 -0 -0 -0</pose>
            <velocity>-4e-05 1.6e-05 0 0 -0 0</velocity>
            <acceleration>-0.359205 0.005607 0 0 -0 3.8e-05</acceleration>
            <wrench>-0.003592 5.6e-05 0 0 -0 0</wrench>
          </link>
          <link name='objL_slideZ'>
            <pose>0.860106 0.205045 0.450003 -0 -0 -0</pose>
            <velocity>-4.1e-05 1.9e-05 0.000536 0 -0 0</velocity>
            <acceleration>-0.360271 0.007248 -8.45047 0 -0 3.7e-05</acceleration>
            <wrench>-0.003603 7.2e-05 -0.084505 0 -0 0</wrench>
          </link>
          <link name='objR'>
            <pose>-0.85455 0.201152 0.45 -7e-06 3e-06 7e-05</pose>
            <velocity>-0.000171 -7.6e-05 4.8e-05 0.001285 -0.003639 0.000348</velocity>
            <acceleration>-0.293512 -0.121502 -0.07247 0.21342 1.31491 1.18722</acceleration>
            <wrench>-0.002935 -0.001215 -0.000725 0 -0 0</wrench>
          </link>
          <link name='objR_rotateX'>
            <pose>-0.85455 0.201152 0.45 -9e-06 0 0</pose>
            <velocity>-0.000258 -0.000155 4.6e-05 -0.000964 -0 -0</velocity>
            <acceleration>-0.396248 -0.207805 -0.076246 0.330273 -0 -4e-06</acceleration>
            <wrench>-0.003962 -0.002078 -0.000762 0 -0 0</wrench>
          </link>
          <link name='objR_rotateY'>
            <pose>-0.85455 0.201152 0.45 -9e-06 5e-06 0</pose>
            <velocity>-0.000251 -0.000151 4.6e-05 -0.000965 -0.001282 0</velocity>
            <acceleration>-0.388931 -0.204127 -0.076203 0.329844 -1.26926 6e-06</acceleration>
            <wrench>-0.003889 -0.002041 -0.000762 0 -0 0</wrench>
          </link>
          <link name='objR_slideX'>
            <pose>-0.85455 0.20 0.45 0 -0 0</pose>
            <velocity>-0.00026 0 0 0 -0 0</velocity>
            <acceleration>-0.397673 -0 0 0 -0 2e-06</acceleration>
            <wrench>-0.003977 -0 0 0 -0 0</wrench>
          </link>
          <link name='objR_slideY'>
            <pose>-0.85455 0.201152 0.45 0 -0 0</pose>
            <velocity>-0.000263 -0.000152 0 0 -0 0</velocity>
            <acceleration>-0.400567 -0.205485 0 0 0 -4e-06</acceleration>
            <wrench>-0.004006 -0.002055 0 0 -0 0</wrench>
          </link>
          <link name='objR_slideZ'>
            <pose>-0.85455 0.201152 0.45 0 -0 0</pose>
            <velocity>-0.000263 -0.000155 4.6e-05 0 -0 0</velocity>
            <acceleration>-0.400115 -0.20824 -0.07581 0 0 -4e-06</acceleration>
            <wrench>-0.004001 -0.002082 -0.000758 0 -0 0</wrench>
          </link>
        </model>
        <model name='environment'>
          <pose>0 0 0 0 -0 0</pose>
          <scale>1 1 1</scale>
          <link name='shelf'>
            <pose>0 0 0 0 -0 0</pose>
            <velocity>0 0 0 0 9e-06 0</velocity>
            <acceleration>0 2e-06 0 -1e-06 0.017687 2.6e-05</acceleration>
            <wrench>7e-05 0.000508 0.000154 0 -0 0</wrench>
          </link>
        </model>
        <model name='ground_plane'>
          <pose>0 0 0 0 -0 0</pose>
          <scale>1 1 1</scale>
          <link name='link'>
            <pose>0 0 0 0 -0 0</pose>
            <velocity>0 0 0 0 -0 0</velocity>
            <acceleration>0 0 0 0 -0 0</acceleration>
            <wrench>0 0 0 0 -0 0</wrench>
          </link>
        </model>
        <light name='sun'>
          <pose>0 0 10 0 -0 0</pose>
        </light>
      </state>
      <gui fullscreen='0'>
        <camera name='user_camera'>
          <pose>-0.004972 -2.16765 1.87702 0 0.557794 1.5482</pose>
          <view_controller>orbit</view_controller>
          <projection_type>perspective</projection_type>
        </camera>
      </gui>
    </world>
  </sdf>
